Workbook
Name TariefLocaties: Locaties!$G$2:$G$15
Name NaamTarieven: Tarieven!$A$2:$A$15
Name DocentenTarieven: Docenten!$G$2:$G$15
Name Locatienaam: Locaties!$A$2:$A$15
Name Naamdocent: Docenten!$A$2:$A$15

Sheet Doel vs Werkelijkheid
A1: § | B1: Gewenst salaris | C1: Ledenaantal (werkelijk) | D1: leden aantal (verwacht) | E1: Actieve leden (verwacht) | F1: Actieve leden | G1: Omzet (werkelijk) | H1: Uitgaven (werkelijk) | I1: Percentage kosten | J1: Status | K1: Brutowinst (werkelijk) | L1: Reserveren inkomstenbelasting | M1: Nettowinst | N1: Salaris | O1: Banksaldo na salaris | P1: Belasting achterstand
A2: augustus | B2: 3000 | C2: 197 | D2: 200 | E2: 340 | F2: =Augustus!AF9 -> 390 | G2: =Augustus!$AF$3+'Extra activiteiten'!K2+Jaarbetalingen!AI3 -> 59241.19 | H2: =Augustus!$AF$5+Augustus!$AF$6 -> 4644.58 | I2: =SUM(H2/G2)*1 -> 0.078401193 | K2: =G2-H2 -> 54596.61 | L2: =IF((K2 / 1) *Inkomstenbelasting!$H$19 < 0, 0, (K2 / 1) * Inkomstenbelasting!$H$19) -> 17696.972 | M2: =K2-L2 -> 36899.638 | N2: =B2 -> 3000 | O2: =M2-N2-P2 -> 23899.638 | P2: 10000
A3: september | B3: 3250 | D3: 220 | E3: 360 | F3: =September!AF9 -> 387 | G3: =September!$AF$3+'Extra activiteiten'!K3 -> 18365.928 | H3: =September!$AF$5+September!$AF$6 -> 14419.3 | I3: =SUM(H3/G3)*1 -> 0.78511143 | K3: =G3-H3 -> 3946.628 | L3: =IF((K3 / 1) *Inkomstenbelasting!$H$19 < 0, 0, (K3 / 1) * Inkomstenbelasting!$H$19) -> 1279.2619 | M3: =K3-L3 -> 2667.3661 | N3: =B3 -> 3250 | O3: =(O2+M3)-N3-P3 -> 23317.004
A4: oktober | B4: 3250 | D4: 230 | E4: 370 | F4: =Oktober!AF9 -> 395 | G4: =Oktober!$AF$3+'Extra activiteiten'!K4 -> 7428.878 | H4: =Oktober!$AF$5+Oktober!$AF$6 -> 8730.34 | I4: =SUM(H4/G4)*1 -> 1.1751896 | K4: =G4-H4 -> -1301.462 | L4: =IF((K4 / 1) *Inkomstenbelasting!$H$19 < 0, 0, (K4 / 1) * Inkomstenbelasting!$H$19) -> 0 | M4: =K4-L4 -> -1301.462 | N4: =B4 -> 3250 | O4: =(O3+M4)-N4-P4 -> 9638.5421 | P4: 9127
A5: november | B5: 3250 | D5: 240 | E5: 380 | F5: =November!AF9 -> 423 | G5: =November!$AF$3+'Extra activiteiten'!K5 -> 7399.3537 | H5: =November!$AF$5+November!$AF$6 -> 7159.92 | I5: =SUM(H5/G5)*1 -> 0.96764127 | K5: =G5-H5 -> 239.43367 | L5: =IF((K5 / 1) *Inkomstenbelasting!$H$19 < 0, 0, (K5 / 1) * Inkomstenbelasting!$H$19) -> 77.610146 | M5: =K5-L5 -> 161.82352 | N5: =B5 -> 3250 | O5: =(O4+M5)-N5-P5 -> 6550.3656
A6: december | B6: 3250 | D6: 245 | E6: 385 | F6: =December!AF9 -> 411 | G6: =December!$AF$3+'Extra activiteiten'!K6 -> 16530.104 | H6: =December!$AF$5+December!$AF$6 -> 7754.54 | I6: =SUM(H6/G6)*1 -> 0.46911624 | K6: =G6-H6 -> 8775.5637 | L6: =IF((K6 / 1) *Inkomstenbelasting!$H$19 < 0, 0, (K6 / 1) * Inkomstenbelasting!$H$19) -> 2844.5155 | M6: =K6-L6 -> 5931.0482 | N6: =B6 -> 3250 | O6: =(O5+M6)-N6-P6 -> 9231.4138
A7: januari | B7: 3250 | D7: 250 | E7: 390 | F7: =Januari!AF9 -> 459 | G7: =Januari!$AF$3+'Extra activiteiten'!K7 -> 10154.22 | H7: =Januari!$AF$5+Januari!$AF$6 -> 10118.52 | I7: =SUM(H7/G7)*1 -> 0.99648419 | K7: =G7-H7 -> 35.700333 | L7: =IF((K7 / 1) *Inkomstenbelasting!$H$19 < 0, 0, (K7 / 1) * Inkomstenbelasting!$H$19) -> 11.571924 | M7: =K7-L7 -> 24.12841 | N7: =B7 -> 3250 | O7: =(O6+M7)-N7-P7 -> 6005.5422
A8: februari | B8: 3250 | D8: 260 | E8: 400 | F8: =Februari!AF9 -> 465 | G8: =Februari!$AF$3+'Extra activiteiten'!K8 -> 8500.4203 | H8: =Februari!$AF$5+Februari!$AF$6 -> 7697.52 | I8: =SUM(H8/G8)*1 -> 0.90554581 | K8: =G8-H8 -> 802.90033 | L8: =IF((K8 / 1) *Inkomstenbelasting!$H$19 < 0, 0, (K8 / 1) * Inkomstenbelasting!$H$19) -> 260.25251 | M8: =K8-L8 -> 542.64783 | N8: =B8 -> 3250 | O8: =(O7+M8)-N8-P8 -> 3298.19
A9: maart | B9: 3250 | D9: 280 | E9: 420 | F9: =Maart!AF9 -> 468 | G9: =Maart!$AF$3+'Extra activiteiten'!K9 -> 10556.35 | H9: =Maart!$AF$5+Maart!$AF$6 -> 11061.67 | I9: =SUM(H9/G9)*1 -> 1.0478688 | K9: =G9-H9 -> -505.31967 | L9: =IF((K9 / 1) *Inkomstenbelasting!$H$19 < 0, 0, (K9 / 1) * Inkomstenbelasting!$H$19) -> 0 | M9: =K9-L9 -> -505.31967 | N9: =B9 -> 3250 | O9: =(O8+M9)-N9-P9 -> -457.12964
A10: april | B10: 3250 | D10: 287 | E10: 427 | F10: =April!AF9 -> 468 | G10: =April!$AF$3+'Extra activiteiten'!K10 -> 8648.3503 | H10: =April!$AF$5+April!$AF$6 -> 6342.34 | I10: =SUM(H10/G10)*1 -> 0.73335836 | K10: =G10-H10 -> 2306.0103 | L10: =IF((K10 / 1) *Inkomstenbelasting!$H$19 < 0, 0, (K10 / 1) * Inkomstenbelasting!$H$19) -> 747.47132 | M10: =K10-L10 -> 1558.539 | N10: =B10 -> 3250 | O10: =(O9+M10)-N10-P10 -> -2148.5906
A11: mei | B11: 3250 | D11: 287 | E11: 427 | F11: =Mei!AF9 -> 461 | G11: =Mei!$AF$3+'Extra activiteiten'!K11 -> 49171.35 | H11: =Mei!$AF$5+Mei!$AF$6 -> 31658.94 | I11: =SUM(H11/G11)*1 -> 0.64384931 | K11: =G11-H11 -> 17512.41 | L11: =IF((K11 / 1) *Inkomstenbelasting!$H$19 < 0, 0, (K11 / 1) * Inkomstenbelasting!$H$19) -> 5676.4813 | M11: =K11-L11 -> 11835.929 | N11: =B11 -> 3250 | O11: =(O10+M11)-N11-P11 -> 6437.3384
A12: juni | B12: 3250 | D12: 295 | E12: 435 | F12: =Juni!AF9 -> 461 | G12: =Juni!$AF$3+'Extra activiteiten'!K12 -> 8713.8503 | H12: =Juni!$AF$5+Juni!$AF$6 -> 6642.78 | I12: =SUM(H12/G12)*1 -> 0.76232432 | K12: =G12-H12 -> 2071.0703 | L12: =IF((K12 / 1) *Inkomstenbelasting!$H$19 < 0, 0, (K12 / 1) * Inkomstenbelasting!$H$19) -> 671.31775 | M12: =K12-L12 -> 1399.7526 | N12: =B12 -> 3250 | O12: =(O11+M12)-N12-P12 -> 4587.091
A13: juli | B13: 3250 | F13: =Juli!AF9 -> 461 | G13: =Juli!$AF$3+'Extra activiteiten'!K13 -> 400 | H13: =Juli!$AF$5+Juli!$AF$6 -> 2424.99 | I13: =SUM(H13/G13)*1 -> 6.062475 | K13: =G13-H13 -> -2024.99 | L13: =IF((K13 / 1) *Inkomstenbelasting!$H$19 < 0, 0, (K13 / 1) * Inkomstenbelasting!$H$19) -> 0 | M13: =K13-L13 -> -2024.99 | N13: =B13 -> 3250 | O13: =(O12+M13)-N13-P13 -> -687.89899
A14: Totaal: | B14: =SUM(B2:B13) -> 38750 | F14: =September!AF20 | G14: =SUM(G2:G13) -> 205110 | H14: =SUM(H2:H13) -> 118655.44 | I14: =SUM(H14/G14)*1 -> 0.57849662 | K14: =SUM(K2:K13) -> 86454.555 | L14: =SUM(L2:L13) -> 29265.454 | M14: =SUM(M2:M13) -> 57189.101 | N14: =SUM(N2:N13) -> 38750 | O14: =C14 | P14: =SUM(P2:P13) -> 19127
E16: Worst | F16: 0.18 | G16: 403.56
B17: bijgewerkt: 17 feb | E17: Beter | F17: 0.234 | G17: 422.028
B18: Zoey wassenaar | E18: Best | F18: 0.3 | G18: 444.6
B19: Drukzo 99,60

Sheet Docenten
A1: Naam docent | B1: Aantal uren per week | C1: Uurloon | D1: Reiskosten per week | E1: Niveau docent | F1: Datum indiensttreding | G1: Daadwerkelijk uurtarief
A2: Eigenaar | B2: 13 | C2: 0 | D2: 0 | E2: Ervaren | F2: 44197 | G2: =(C2*B2+D2)/B2 -> 0
A3: Nova | B3: 8 | C3: 22.5 | D3: 0 | E3: Ervaren | F3: 45170 | G3: =(C3*B3+D3)/B3 -> 22.5
A4: Frederique | B4: 5 | C4: 12.5 | D4: 0 | E4: Starter | F4: 45536 | G4: =(C4*B4+D4)/B4 -> 12.5
A5: Julia | B5: 5 | C5: 15 | D5: 0 | E5: Starter | F5: 45536 | G5: =(C5*B5+D5)/B5 -> 15
A6: Lotte | B6: 2 | C6: 22.5 | D6: 0 | E6: Ervaren | F6: 45901 | G6: =(C6*B6+D6)/B6 -> 22.5
A7: Bianca | B7: 3 | C7: 20 | D7: 0 | E7: Gemiddeld | F7: 45901 | G7: =(C7*B7+D7)/B7 -> 20
A8: Tess | B8: 2 | C8: 17.5 | D8: 0 | E8: Starter | F8: 45901 | G8: =(C8*B8+D8)/B8 -> 17.5
A9: Opvang T | B9: 1 | C9: 45 | D9: 0 | E9: Inval docent | F9: 45901 | G9: =(C9*B9+D9)/B9 -> 45
A10: Fre + 2 | B10: 1 | C10: 18 | D10: 0 | E10: Starter | G10: =(C10*B10+D10)/B10 -> 18
A11: Fre +1 | B11: 1 | C11: 5.5 | D11: 0 | E11: Starter | G11: =(C11*B11+D11)/B11 -> 5.5
A12: Tess +1 | B12: 1 | C12: 21.5 | D12: 0 | E12: Gemiddeld | G12: =(C12*B12+D12)/B12 -> 21.5
A13: Ilja + 1 | B13: 1 | C13: 3.50 | D13: 0 | E13: Ervaren | G13: =(C13*B13+D13)/B13 -> #VALUE!
A14: Dion + 3 | B14: 2 | C14: 34 | D14: 0 | E14: Ervaren | G14: =(C14*B14+D14)/B14 -> 34
G15: =(C15*B15+D15)/B15 -> #DIV/0!
G16: =(C16*B16+D16)/B16 -> #DIV/0!
G17: =(C17*B17+D17)/B17 -> #DIV/0!
G18: =(C18*B18+D18)/B18 -> #DIV/0!
G19: =(C19*B19+D19)/B19 -> #DIV/0!
G20: =(C20*B20+D20)/B20 -> #DIV/0!
G21: =(C21*B21+D21)/B21 -> #DIV/0!
G22: =(C22*B22+D22)/B22 -> #DIV/0!
G23: =(C23*B23+D23)/B23 -> #DIV/0!
G24: =(C24*B24+D24)/B24 -> #DIV/0!
G25: =(C25*B25+D25)/B25 -> #DIV/0!
G26: =(C26*B26+D26)/B26 -> #DIV/0!
... G30: =(C30*B30+D30)/B30 -> #DIV/0!

Sheet Locaties
A1: Naam locatie | B1: Uurtarief | C1: Aantal uren per week | D1: Lesweken per jaar | E1: Bijkomende jaarlijkse kosten | F1: Opmerkingen | G1: Daadwerkelijk Uurtarief
A2: Santpoort Noord | B2: 14.2 | C2: 15 | D2: 36 | E2: 0 | G2: =(E2/D2/C2)+B2 -> 14.2
A3: Santpoort Zuid | B3: 18.9 | C3: 18 | D3: 36 | E3: 0 | G3: =(E3/D3/C3)+B3 -> 18.9
G4: =(E4/D4/C4)+B4 -> #DIV/0!
G5: =(E5/D5/C5)+B5 -> #DIV/0!
G6: =(E6/D6/C6)+B6 -> #DIV/0!
G7: =(E7/D7/C7)+B7 -> #DIV/0!
G8: =(E8/D8/C8)+B8 -> #DIV/0!
G9: =(E9/D9/C9)+B9 -> #DIV/0!
G10: =(E10/D10/C10)+B10 -> #DIV/0!
G11: =(E11/D11/C11)+B11 -> #DIV/0!
G12: =(E12/D12/C12)+B12 -> #DIV/0!
G13: =(E13/D13/C13)+B13 -> #DIV/0!
G14: =(E14/D14/C14)+B14 -> #DIV/0!
G15: =(E15/D15/C15)+B15 -> #DIV/0!

Sheet Tarieven
A1: Naam lidmaatschap | B1: Tarief per jaar | C1: Aantal keer per week | D1: Betaal termijnen | E1: Leeftijd | F1: BTW tarief % | G1: BTW Bedrag | H1: Netto tarief | I1: Per termijn (excl btw) | J1: Tarief per les/per termijn (excl btw)
A2: Geen betaling | B2: 0 | C2: 1 | D2: 1 | F2: 0 | G2: =B2 / 1 * M2 -> 0 | H2: =B2-G2 -> 0 | I2: =H2/D2 -> 0 | J2: =I2/C2 -> 0 | M2: =F2 -> 0
A3: Aangepast tarief | C3: 1 | D3: 1 | F3: 0 | G3: =B3 / 1 * M3 -> 0 | H3: =B3-G3 -> 0 | I3: =H3/D3 -> 0 | J3: =I3/C3 -> 0 | M3: =F3 -> 0
A4: 1x per week | B4: 279 | C4: 1 | D4: 1 | E4: tot 18 jaar | F4: 0 | G4: =B4 / 1 * M4 -> 0 | H4: =B4-G4 -> 279 | I4: =H4/D4 -> 279 | J4: =I4/C4 -> 279 | M4: =F4 -> 0
A5: 1x per week abbo | B5: 310 | C5: 1 | D5: 10 | E5: tot 18 jaar | F5: 0 | G5: =B5 / 1 * M5 -> 0 | H5: =B5-G5 -> 310 | I5: =H5/D5 -> 31 | J5: =I5/C5 -> 31 | M5: =F5 -> 0
A6: 2x per week | B6: 558 | C6: 2 | D6: 1 | E6: tot 18 jaar | F6: 0 | G6: =B6 / 1 * M6 -> 0 | H6: =B6-G6 -> 558 | I6: =H6/D6 -> 558 | J6: =I6/C6 -> 279 | M6: =F6 -> 0
A7: 2x per week abbo | B7: 571 | C7: 2 | D7: 10 | E7: tot 18 jaar | F7: 0 | G7: =B7 / 1 * M7 -> 0 | H7: =B7-G7 -> 571 | I7: =H7/D7 -> 57.1 | J7: =I7/C7 -> 28.55 | M7: =F7 -> 0
A8: 3x per week | B8: 837 | C8: 3 | D8: 1 | E8: tot 18 jaar | F8: 0 | G8: =B8 / 1 * M8 -> 0 | H8: =B8-G8 -> 837 | I8: =H8/D8 -> 837 | J8: =I8/C8 -> 279 | M8: =F8 -> 0
A9: 3x per week abbo | B9: 868 | C9: 3 | D9: 10 | E9: tot 18 jaar | F9: 0 | G9: =B9 / 1 * M9 -> 0 | H9: =B9-G9 -> 868 | I9: =H9/D9 -> 86.8 | J9: =I9/C9 -> 28.933333 | M9: =F9 -> 0
A10: Onbeperkt | B10: 1054.5 | C10: 4 | D10: 1 | E10: tot 18 jaar | F10: 0 | G10: =B10 / 1 * M10 -> 0 | H10: =B10-G10 -> 1054.5 | I10: =H10/D10 -> 1054.5 | J10: =I10/C10 -> 263.625 | M10: =F10 -> 0
A11: Onbeperkt abbo | B11: 1080 | C11: 4 | D11: 10 | E11: tot 18 jaar | F11: 0 | G11: =B11 / 1 * M11 -> 0 | H11: =B11-G11 -> 1080 | I11: =H11/D11 -> 108 | J11: =I11/C11 -> 27 | M11: =F11 -> 0
A12: Cheer regulier | B12: 300 | C12: 1 | D12: 1 | E12: tot 18 jaar | F12: 0 | G12: =B12 / 1 * M12 -> 0 | H12: =B12-G12 -> 300 | I12: =H12/D12 -> 300 | J12: =I12/C12 -> 300 | M12: =F12 -> 0
A13: Cheer regulier abbo | B13: 335 | C13: 1 | D13: 10 | E13: tot 18 jaar | F13: 0 | G13: =B13 / 1 * M13 -> 0 | H13: =B13-G13 -> 335 | I13: =H13/D13 -> 33.5 | J13: =I13/C13 -> 33.5 | M13: =F13 -> 0
A14: Cheer regulier +1 | B14: 579 | C14: 2 | D14: 1 | E14: tot 18 | F14: 0 | G14: =B14 / 1 * M14 -> 0 | H14: =B14-G14 -> 579 | I14: =H14/D14 -> 579 | J14: =I14/C14 -> 289.5 | M14: =F14 -> 0
A15: Cheer regulier +1 abbo | B15: 645 | C15: 2 | D15: 10 | E15: tot 18 | F15: 0 | G15: =B15 / 1 * M15 -> 0 | H15: =B15-G15 -> 645 | I15: =H15/D15 -> 64.5 | J15: =I15/C15 -> 32.25 | M15: =F15 -> 0
... A30: Jeugdfonds | B30: 261 | C30: 1 | D30: 1 | E30: tot 18 | F30: 0 | G30: =B30 / 1 * M30 -> 0 | H30: =B30-G30 -> 261 | I30: =H30/D30 -> 261 | J30: =I30/C30 -> 261 | M30: =F30 -> 0
A31: Cheer regulier + onbeperkt | B31: 1147 | C31: 4 | D31: 1 | F31: 0 | G31: =B31 / 1 * M31 -> 0 | H31: =B31-G31 -> 1147 | I31: =H31/D31 -> 1147 | J31: =I31/C31 -> 286.75 | M31: =F31 -> 0
A32: Cheer regulier + onbeperkt abbo | B32: 1778 | C32: 4 | D32: 10 | F32: 0 | G32: =B32 / 1 * M32 -> 0 | H32: =B32-G32 -> 1778 | I32: =H32/D32 -> 177.8 | J32: =I32/C32 -> 44.45 | M32: =F32 -> 0
G33: =B33 / 1 * M33 -> 0 | H33: =B33-G33 -> 0 | I33: =H33/D33 -> #DIV/0! | J33: =I33/C33 -> #DIV/0! | M33: =F33
G34: =B34 / 1 * M34 -> 0 | H34: =B34-G34 -> 0 | I34: =H34/D34 -> #DIV/0! | J34: =I34/C34 -> #DIV/0! | M34: =F34
G35: =B35 / 1 * M35 -> 0 | H35: =B35-G35 -> 0 | I35: =H35/D35 -> #DIV/0! | J35: =I35/C35 -> #DIV/0! | M35: =F35
G36: =B36 / 1 * M36 -> 0 | H36: =B36-G36 -> 0 | I36: =H36/D36 -> #DIV/0! | J36: =I36/C36 -> #DIV/0! | M36: =F36
G37: =B37 / 1 * M37 -> 0 | H37: =B37-G37 -> 0 | I37: =H37/D37 -> #DIV/0! | J37: =I37/C37 -> #DIV/0! | M37: =F37
G38: =B38 / 1 * M38 -> 0 | H38: =B38-G38 -> 0 | I38: =H38/D38 -> #DIV/0! | J38: =I38/C38 -> #DIV/0! | M38: =F38
G39: =B39 / 1 * M39 -> 0 | H39: =B39-G39 -> 0 | I39: =H39/D39 -> #DIV/0! | J39: =I39/C39 -> #DIV/0! | M39: =F39
G40: =B40 / 1 * M40 -> 0 | H40: =B40-G40 -> 0 | I40: =H40/D40 -> #DIV/0! | J40: =I40/C40 -> #DIV/0! | M40: =F40
G41: =B41 / 1 * M41 -> 0 | H41: =B41-G41 -> 0 | I41: =H41/D41 -> #DIV/0! | J41: =I41/C41 -> #DIV/0! | M41: =F41
G42: =B42 / 1 * M42 -> 0 | H42: =B42-G42 -> 0 | I42: =H42/D42 -> #DIV/0! | J42: =I42/C42 -> #DIV/0! | M42: =F42
G43: =B43 / 1 * M43 -> 0 | H43: =B43-G43 -> 0 | I43: =H43/D43 -> #DIV/0! | J43: =I43/C43 -> #DIV/0! | M43: =F43
G44: =B44 / 1 * M44 -> 0 | H44: =B44-G44 -> 0 | I44: =H44/D44 -> #DIV/0! | J44: =I44/C44 -> #DIV/0! | M44: =F44
... G150: =B150 / 1 * M150 -> 0 | H150: =B150-G150 -> 0 | I150: =H150/D150 -> #DIV/0! | J150: =I150/C150 -> #DIV/0! | M150: =F150

Sheet Rooster
A2: Lesdag | B2: Lestijd | C2: Aantal minuten les | D2: Naam les | E2: Docent | F2: Tarief docent | G2: Tarief docent voor deze les | H2: Locatie | I2: Zaalhuur per uur | J2: Zaalhuur per les
F3: =IFERROR(VLOOKUP(E3, Docenten!$A$2:$G$30, 7, FALSE), "0") -> 0 | G3: =SUM(F3/60)*C3 -> 0 | I3: =IFERROR(VLOOKUP(H3, Locaties!$A$2:$G$15, 7, FALSE), "0") -> 0 | J3: =SUM(I3/60)*C3 -> 0
F4: =IFERROR(VLOOKUP(E4, Docenten!$A$2:$G$30, 7, FALSE), "0") -> 0 | G4: =SUM(F4/60)*C4 -> 0 | I4: =IFERROR(VLOOKUP(H4, Locaties!$A$2:$G$15, 7, FALSE), "0") -> 0 | J4: =SUM(I4/60)*C4 -> 0
A5: Maandag | B5: 0.625 | C5: 60 | D5: Kleuterdans | E5: Lotte | F5: =IFERROR(VLOOKUP(E5, Docenten!$A$2:$G$30, 7, FALSE), "0") -> 22.5 | G5: =SUM(F5/60)*C5 -> 22.5 | H5: Santpoort Zuid | I5: =IFERROR(VLOOKUP(H5, Locaties!$A$2:$G$15, 7, FALSE), "0") -> 18.9 | J5: =SUM(I5/60)*C5 -> 18.9
A6: Maandag | B6: 0.625 | C6: 60 | D6: Streetdance 6+ | E6: Lotte | F6: =IFERROR(VLOOKUP(E6, Docenten!$A$2:$G$30, 7, FALSE), "0") -> 22.5 | G6: =SUM(F6/60)*C6 -> 22.5 | H6: Santpoort Zuid | I6: =IFERROR(VLOOKUP(H6, Locaties!$A$2:$G$15, 7, FALSE), "0") -> 18.9 | J6: =SUM(I6/60)*C6 -> 18.9
A7: Maandag | B7: 0.66666667 | C7: 60 | D7: Urban-Pop-Show 10+ | E7: Lotte | F7: =IFERROR(VLOOKUP(E7, Docenten!$A$2:$G$30, 7, FALSE), "0") -> 22.5 | G7: =SUM(F7/60)*C7 -> 22.5 | H7: Santpoort Zuid | I7: =IFERROR(VLOOKUP(H7, Locaties!$A$2:$G$15, 7, FALSE), "0") -> 18.9 | J7: =SUM(I7/60)*C7 -> 18.9
A8: Maandag | B8: 0.70833333 | C8: 60 | D8: Urban-Pop-Show 12+ | E8: Nova | F8: =IFERROR(VLOOKUP(E8, Docenten!$A$2:$G$30, 7, FALSE), "0") -> 22.5 | G8: =SUM(F8/60)*C8 -> 22.5 | H8: Santpoort Zuid | I8: =IFERROR(VLOOKUP(H8, Locaties!$A$2:$G$15, 7, FALSE), "0") -> 18.9 | J8: =SUM(I8/60)*C8 -> 18.9
A9: Maandag | B9: 0.75 | C9: 60 | D9: Selectie Show | E9: Nova | F9: =IFERROR(VLOOKUP(E9, Docenten!$A$2:$G$30, 7, FALSE), "0") -> 22.5 | G9: =SUM(F9/60)*C9 -> 22.5 | H9: Santpoort Zuid | I9: =IFERROR(VLOOKUP(H9, Locaties!$A$2:$G$15, 7, FALSE), "0") -> 18.9 | J9: =SUM(I9/60)*C9 -> 18.9
A10: Maandag | B10: 0.79166667 | C10: 60 | D10: Commercial 16+ | E10: Nova | F10: =IFERROR(VLOOKUP(E10, Docenten!$A$2:$G$30, 7, FALSE), "0") -> 22.5 | G10: =SUM(F10/60)*C10 -> 22.5 | H10: Santpoort Zuid | I10: =IFERROR(VLOOKUP(H10, Locaties!$A$2:$G$15, 7, FALSE), "0") -> 18.9 | J10: =SUM(I10/60)*C10 -> 18.9
A11: Maandag | B11: 0.83333333 | C11: 60 | D11: Commercial 20+ | E11: Nova | F11: =IFERROR(VLOOKUP(E11, Docenten!$A$2:$G$30, 7, FALSE), "0") -> 22.5 | G11: =SUM(F11/60)*C11 -> 22.5 | H11: Santpoort Zuid | I11: =IFERROR(VLOOKUP(H11, Locaties!$A$2:$G$15, 7, FALSE), "0") -> 18.9 | J11: =SUM(I11/60)*C11 -> 18.9
A12: Maandag | B12: 0.875 | C12: 60 | D12: Jazz 20+ | E12: Nova | F12: =IFERROR(VLOOKUP(E12, Docenten!$A$2:$G$30, 7, FALSE), "0") -> 22.5 | G12: =SUM(F12/60)*C12 -> 22.5 | H12: Santpoort Zuid | I12: =IFERROR(VLOOKUP(H12, Locaties!$A$2:$G$15, 7, FALSE), "0") -> 18.9 | J12: =SUM(I12/60)*C12 -> 18.9
A13: Maandag | B13: 0.66666667 | C13: 60 | D13: Streetdance 6+ | E13: Julia | F13: =IFERROR(VLOOKUP(E13, Docenten!$A$2:$G$30, 7, FALSE), "0") -> 15 | G13: =SUM(F13/60)*C13 -> 15 | H13: Santpoort Noord | I13: =IFERROR(VLOOKUP(H13, Locaties!$A$2:$G$15, 7, FALSE), "0") -> 14.2 | J13: =SUM(I13/60)*C13 -> 14.2
A14: Maandag | B14: 0.70833333 | C14: 60 | D14: Streetdance 8+ | E14: Julia | F14: =IFERROR(VLOOKUP(E14, Docenten!$A$2:$G$30, 7, FALSE), "0") -> 15 | G14: =SUM(F14/60)*C14 -> 15 | H14: Santpoort Noord | I14: =IFERROR(VLOOKUP(H14, Locaties!$A$2:$G$15, 7, FALSE), "0") -> 14.2 | J14: =SUM(I14/60)*C14 -> 14.2
A15: Dinsdag | B15: 0.66666667 | C15: 60 | D15: Modern 8+ | E15: Eigenaar | F15: =IFERROR(VLOOKUP(E15, Docenten!$A$2:$G$30, 7, FALSE), "0") -> 0 | G15: =SUM(F15/60)*C15 -> 0 | H15: Santpoort Zuid | I15: =IFERROR(VLOOKUP(H15, Locaties!$A$2:$G$15, 7, FALSE), "0") -> 18.9 | J15: =SUM(I15/60)*C15 -> 18.9
A16: Dinsdag | B16: 0.70833333 | C16: 60 | D16: Selectie show 8+ | E16: Eigenaar | F16: =IFERROR(VLOOKUP(E16, Docenten!$A$2:$G$30, 7, FALSE), "0") -> 0 | G16: =SUM(F16/60)*C16 -> 0 | H16: Santpoort Zuid | I16: =IFERROR(VLOOKUP(H16, Locaties!$A$2:$G$15, 7, FALSE), "0") -> 18.9 | J16: =SUM(I16/60)*C16 -> 18.9
... A23: Woensdag | B23: 0.77083333 | C23: 60 | D23: Show 12+ | E23: Eigenaar | F23: =IFERROR(VLOOKUP(E23, Docenten!$A$2:$G$30, 7, FALSE), "0") -> 0 | G23: =SUM(F23/60)*C23 -> 0 | H23: Santpoort Noord | I23: =IFERROR(VLOOKUP(H23, Locaties!$A$2:$G$15, 7, FALSE), "0") -> 14.2 | J23: =SUM(I23/60)*C23 -> 14.2
I24: =IFERROR(VLOOKUP(H24, Locaties!$A$2:$G$15, 7, FALSE), "0") -> 0 | J24: =SUM(I24/60)*C24 -> 0
A25: Donderdag | B25: 0.64583333 | C25: 60 | D25: Showdance 6+ | E25: Eigenaar | F25: =IFERROR(VLOOKUP(E25, Docenten!$A$2:$G$30, 7, FALSE), "0") -> 0 | G25: =SUM(F25/60)*C25 -> 0 | H25: Santpoort Zuid | I25: =IFERROR(VLOOKUP(H25, Locaties!$A$2:$G$15, 7, FALSE), "0") -> 18.9 | J25: =SUM(I25/60)*C25 -> 18.9
A26: Donderdag | B26: 0.6875 | C26: 60 | D26: Showdance 8+ | E26: Eigenaar | F26: =IFERROR(VLOOKUP(E26, Docenten!$A$2:$G$30, 7, FALSE), "0") -> 0 | G26: =SUM(F26/60)*C26 -> 0 | H26: Santpoort Zuid | I26: =IFERROR(VLOOKUP(H26, Locaties!$A$2:$G$15, 7, FALSE), "0") -> 18.9 | J26: =SUM(I26/60)*C26 -> 18.9
A27: Donderdag | B27: 0.72916667 | C27: 60 | D27: Modern 14+ | E27: Eigenaar | F27: =IFERROR(VLOOKUP(E27, Docenten!$A$2:$G$30, 7, FALSE), "0") -> 0 | G27: =SUM(F27/60)*C27 -> 0 | H27: Santpoort Zuid | I27: =IFERROR(VLOOKUP(H27, Locaties!$A$2:$G$15, 7, FALSE), "0") -> 18.9 | J27: =SUM(I27/60)*C27 -> 18.9
A28: Donderdag | B28: 0.77083333 | C28: 60 | D28: Commercial 14+ | E28: Nova | F28: =IFERROR(VLOOKUP(E28, Docenten!$A$2:$G$30, 7, FALSE), "0") -> 22.5 | G28: =SUM(F28/60)*C28 -> 22.5 | H28: Santpoort Zuid | I28: =IFERROR(VLOOKUP(H28, Locaties!$A$2:$G$15, 7, FALSE), "0") -> 18.9 | J28: =SUM(I28/60)*C28 -> 18.9
A29: Donderdag | B29: 0.8125 | C29: 60 | D29: Selectie Hiphop 16+ | E29: Nova | F29: =IFERROR(VLOOKUP(E29, Docenten!$A$2:$G$30, 7, FALSE), "0") -> 22.5 | G29: =SUM(F29/60)*C29 -> 22.5 | H29: Santpoort Zuid | I29: =IFERROR(VLOOKUP(H29, Locaties!$A$2:$G$15, 7, FALSE), "0") -> 18.9 | J29: =SUM(I29/60)*C29 -> 18.9
A30: Donderdag | B30: 0.85416667 | C30: 60 | D30: Modern 16+ | E30: Nova | F30: =IFERROR(VLOOKUP(E30, Docenten!$A$2:$G$30, 7, FALSE), "0") -> 22.5 | G30: =SUM(F30/60)*C30 -> 22.5 | H30: Santpoort Zuid | I30: =IFERROR(VLOOKUP(H30, Locaties!$A$2:$G$15, 7, FALSE), "0") -> 18.9 | J30: =SUM(I30/60)*C30 -> 18.9
A31: Vrijdag | B31: 0.625 | C31: 60 | D31: Selectie Hiphop 8+ | E31: Eigenaar | F31: =IFERROR(VLOOKUP(E31, Docenten!$A$2:$G$30, 7, FALSE), "0") -> 0 | G31: =SUM(F31/60)*C31 -> 0 | H31: Santpoort Zuid | I31: =IFERROR(VLOOKUP(H31, Locaties!$A$2:$G$15, 7, FALSE), "0") -> 18.9 | J31: =SUM(I31/60)*C31 -> 18.9
A32: Vrijdag | B32: 0.66666667 | C32: 60 | D32: Cheer 8+ | E32: Eigenaar | F32: =IFERROR(VLOOKUP(E32, Docenten!$A$2:$G$30, 7, FALSE), "0") -> 0 | G32: =SUM(F32/60)*C32 -> 0 | H32: Santpoort Zuid | I32: =IFERROR(VLOOKUP(H32, Locaties!$A$2:$G$15, 7, FALSE), "0") -> 18.9 | J32: =SUM(I32/60)*C32 -> 18.9
A33: Vrijdag | B33: 0.70833333 | C33: 60 | D33: Cheer 12+ | E33: Eigenaar | F33: =IFERROR(VLOOKUP(E33, Docenten!$A$2:$G$30, 7, FALSE), "0") -> 0 | G33: =SUM(F33/60)*C33 -> 0 | H33: Santpoort Zuid | I33: =IFERROR(VLOOKUP(H33, Locaties!$A$2:$G$15, 7, FALSE), "0") -> 18.9 | J33: =SUM(I33/60)*C33 -> 18.9
A34: Vrijdag | B34: 0.75 | C34: 60 | D34: Urban-pop-Show 11+ | E34: Eigenaar | F34: =IFERROR(VLOOKUP(E34, Docenten!$A$2:$G$30, 7, FALSE), "0") -> 0 | G34: =SUM(F34/60)*C34 -> 0 | H34: Santpoort Noord | I34: =IFERROR(VLOOKUP(H34, Locaties!$A$2:$G$15, 7, FALSE), "0") -> 14.2 | J34: =SUM(I34/60)*C34 -> 14.2
A35: Zaterdag | B35: 0.375 | C35: 60 | D35: Peuters | E35: Frederique | F35: =IFERROR(VLOOKUP(E35, Docenten!$A$2:$G$30, 7, FALSE), "0") -> 12.5 | G35: =SUM(F35/60)*C35 -> 12.5 | H35: Santpoort Noord | I35: =IFERROR(VLOOKUP(H35, Locaties!$A$2:$G$15, 7, FALSE), "0") -> 14.2 | J35: =SUM(I35/60)*C35 -> 14.2
A36: Zaterdag | B36: 0.40625 | C36: 60 | D36: Kleuters | E36: Frederique | F36: =IFERROR(VLOOKUP(E36, Docenten!$A$2:$G$30, 7, FALSE), "0") -> 12.5 | G36: =SUM(F36/60)*C36 -> 12.5 | H36: Santpoort Noord | I36: =IFERROR(VLOOKUP(H36, Locaties!$A$2:$G$15, 7, FALSE), "0") -> 14.2 | J36: =SUM(I36/60)*C36 -> 14.2
... A40: Zaterdag | B40: 0.44791667 | C40: 60 | D40: Kleuters | E40: Tess | F40: =IFERROR(VLOOKUP(E40, Docenten!$A$2:$G$30, 7, FALSE), "0") -> 17.5 | G40: =SUM(F40/60)*C40 -> 17.5 | H40: Santpoort Zuid | I40: =IFERROR(VLOOKUP(H40, Locaties!$A$2:$G$15, 7, FALSE), "0") -> 18.9 | J40: =SUM(I40/60)*C40 -> 18.9
F41: =IFERROR(VLOOKUP(E41, Docenten!$A$2:$G$30, 7, FALSE), "0") -> 0 | G41: =SUM(F41/60)*C41 -> 0 | I41: =IFERROR(VLOOKUP(H41, Locaties!$A$2:$G$15, 7, FALSE), "0") -> 0 | J41: =SUM(I41/60)*C41 -> 0
F42: =IFERROR(VLOOKUP(E42, Docenten!$A$2:$G$30, 7, FALSE), "0") -> 0 | G42: =SUM(F42/60)*C42 -> 0 | I42: =IFERROR(VLOOKUP(H42, Locaties!$A$2:$G$15, 7, FALSE), "0") -> 0 | J42: =SUM(I42/60)*C42 -> 0
A43: Maandag | B43: 0.39583333 | C43: 60 | D43: Kinderopvang | E43: Opvang T | F43: =IFERROR(VLOOKUP(E43, Docenten!$A$2:$G$30, 7, FALSE), "0") -> 45 | G43: =SUM(F43/60)*C43 -> 45 | I43: =IFERROR(VLOOKUP(H43, Locaties!$A$2:$G$15, 7, FALSE), "0") -> 0 | J43: =SUM(I43/60)*C43 -> 0
A44: Vrijdag | B44: 0.79166667 | C44: 0.83333333 | D44: Prive training | E44: Eigenaar | F44: =IFERROR(VLOOKUP(E44, Docenten!$A$2:$G$30, 7, FALSE), "0") -> 0 | G44: =SUM(F44/60)*C44 -> 0 | I44: =IFERROR(VLOOKUP(H44, Locaties!$A$2:$G$15, 7, FALSE), "0") -> 0 | J44: =SUM(I44/60)*C44 -> 0
A45: Zaterdag | B45: 0.5625 | C45: 0.60416667 | D45: Prive training | E45: Eigenaar | F45: =IFERROR(VLOOKUP(E45, Docenten!$A$2:$G$30, 7, FALSE), "0") -> 0 | G45: =SUM(F45/60)*C45 -> 0 | I45: =IFERROR(VLOOKUP(H45, Locaties!$A$2:$G$15, 7, FALSE), "0") -> 0 | J45: =SUM(I45/60)*C45 -> 0
F46: =IFERROR(VLOOKUP(E46, Docenten!$A$2:$G$30, 7, FALSE), "0") -> 0 | G46: =SUM(F46/60)*C46 -> 0 | I46: =IFERROR(VLOOKUP(H46, Locaties!$A$2:$G$15, 7, FALSE), "0") -> 0 | J46: =SUM(I46/60)*C46 -> 0
F47: =IFERROR(VLOOKUP(E47, Docenten!$A$2:$G$30, 7, FALSE), "0") -> 0 | G47: =SUM(F47/60)*C47 -> 0 | I47: =IFERROR(VLOOKUP(H47, Locaties!$A$2:$G$15, 7, FALSE), "0") -> 0 | J47: =SUM(I47/60)*C47 -> 0
A48: Donderdag | B48: 0.75 | C48: 60 | D48: Turnen 6+ | E48: Dion + 3 | F48: =IFERROR(VLOOKUP(E48, Docenten!$A$2:$G$30, 7, FALSE), "0") -> 34 | G48: =SUM(F48/60)*C48 -> 34 | H48: Santpoort Noord | I48: =IFERROR(VLOOKUP(H48, Locaties!$A$2:$G$15, 7, FALSE), "0") -> 14.2 | J48: =SUM(I48/60)*C48 -> 14.2
A49: Donderdag | B49: 0.79166667 | C49: 60 | D49: Turnen 12+ | E49: Dion + 3 | F49: =IFERROR(VLOOKUP(E49, Docenten!$A$2:$G$30, 7, FALSE), "0") -> 34 | G49: =SUM(F49/60)*C49 -> 34 | H49: Santpoort Noord | I49: =IFERROR(VLOOKUP(H49, Locaties!$A$2:$G$15, 7, FALSE), "0") -> 14.2 | J49: =SUM(I49/60)*C49 -> 14.2
F50: =IFERROR(VLOOKUP(E50, Docenten!$A$2:$G$30, 7, FALSE), "0") -> 0 | G50: =SUM(F50/60)*C50 -> 0 | I50: =IFERROR(VLOOKUP(H50, Locaties!$A$2:$G$15, 7, FALSE), "0") -> 0 | J50: =SUM(I50/60)*C50 -> 0
...

Sheet Kosten
A1: Kosten | B1: Augustus | C1: September | D1: Oktober | E1: November | F1: December | G1: Januari | H1: Februari | I1: Maart | J1: April | K1: Mei | L1: Juni | M1: Juli
A2: Abbonementen | B2: (Voor Nederland) Let op! Vul de bedragen excl BTW in.
A3: Ledenadministratie | B3: 77.44 | C3: 77.44 | D3: 77.44 | E3: 77.44 | F3: 77.44 | G3: 77.44 | H3: 77.44 | I3: 77.44 | J3: 77.44 | K3: 77.44 | L3: 77.44 | M3: 77.44
A4: ChatGTP | D4: 24.5 | E4: 24.5 | F4: 24.5 | G4: 24.5 | H4: 24.5 | I4: 24.5 | J4: 24.5 | K4: 24.5 | L4: 24.5 | M4: 24.5
A5: Spotify | B5: 10.99 | C5: 10.99 | D5: 10.99 | E5: 10.99 | F5: 10.99 | G5: 10.99 | H5: 10.99 | I5: 10.99 | J5: 10.99 | K5: 10.99 | L5: 10.99 | M5: 10.99
A6: Opslag Kostuums | B6: 213 | C6: 213 | D6: 213 | E6: 213 | F6: 213 | G6: 213 | H6: 213 | I6: 213 | J6: 213 | K6: 213 | L6: 213 | M6: 213
A7: Wix/Canva/Overig | E7: 160 | H7: 109 | L7: 376
A8: Extra zaal huur
A10: Personeel
A11: Administratief medewerker fulltime
A12: Kleding docenten | I12: 130.85
A14: Administratiekosten
A15: kantoorkosten | D15: =110+15.8 -> 125.8 | E15: =15.43+46+274 -> 335.43 | F15: 97 | G15: =130+141+70+13 -> 354 | H15: =276+37.4+347+122++69+9.4 -> 860.8 | I15: =84+37.97+26.99+31+8.75+16.49+209.8 -> 415 | L15: =20+30+186 -> 236
A16: telefoonkosten | B16: 20.56 | C16: 20.56 | D16: 20.56 | E16: 20.56 | F16: 20.56 | G16: 20.56 | H16: 20.56 | I16: 20.56 | J16: 20.56 | K16: 20.56 | L16: 20.56 | M16: 20.56
A17: computerkosten | B17: 639 | L17: 155 | M17: 155
A18: Verzekering | B18: 72.25 | C18: 72.25 | D18: 72.25 | E18: 72.25 | F18: 72.25 | G18: 72.25 | H18: 72.25 | I18: 72.25 | J18: 72.25 | K18: 72.25 | L18: 72.25 | M18: 72.25
A20: Kosten leden
A21: Kostuums aangekocht doorheen jaar | B21: =64+79+10 -> 153 | D21: 63 | E21: =75+22+25+29 -> 151 | F21: =15+170+34+34+37+87+25+92+60 -> 554 | G21: =28.95+21.76+44 -> 94.71 | H21: 610 | L21: =50.64+66.3 -> 116.94
A22: kostuums aangekocht periode show | G22: =74+33+100 -> 207
A23: Selectie teams | B23: =33+245+112+152.3+175+55+96+135 -> 1003.3 | C23: =128+169+99+64+138+152.7-+51+33+29+112.28+119.3+290+13.93+550+30+1630+518+230 -> 4255.21 | D23: =29.66+24.24+24+44 -> 121.9 | F23: 826 | G23: =820+102+200 -> 1122 | H23: 811 | I23: =1000+960+30 -> 1990
A25: Voorstellingskosten | K25: 27200
A29: Marketing en verkoopkosten
A30: advertentie per maand | B30: 50 | E30: 86 | G30: 207 | K30: 50 | L30: 50 | M30: 50
A31: kosten overig werk | B31: =31+27+35 -> 93 | C31: =28+23+10+39.9 -> 100.9 | D31: =36+40+23+22+129 -> 250 | E31: =54+150+90+97+27+78+27+6+20+17 -> 566 | F31: =13+23+79+39+78+40+15+25+30+26+29 -> 397 | G31: =35+25.45+81+63+93+23 -> 320.45 | H31: 222 | I31: =21.15+129 -> 150.15 | J31: =175+20+250 -> 445
A32: representatiekosten | B32: =280.65+240 -> 520.65 | C32: =137+130 -> 267 | D32: =52+277+80+12 -> 421 | E32: =165+107.5+46 -> 318.5 | F32: =155+177 -> 332 | G32: =250+65.5+132+30 -> 477.5 | H32: 125 | I32: =125.8+39.5+43 -> 208.3 | J32: =65+171+55 -> 291
A33: promotiemateriaal | B33: =150+30+91 -> 271 | C33: 921 | D33: 53 | G33: =47.53+56.5 -> 104.03
A34: overige verkoopkosten | L34: 108
A35: coaching | B35: 544.5 | C35: 544.5 | D35: 544.5 | E35: 544.5 | F35: 544.5 | G35: 544.5 | H35: 544.5 | I35: 544.5 | J35: 544.5 | K35: 544.5 | L35: 544.5 | M35: 544.5
A36: Merchandise | C36: 1592 | D36: 294
A38: Vervoerskosten
A39: Verzekering auto | B39: 143 | C39: 143 | D39: 121.75 | E39: 121.75 | F39: 121.75 | G39: 121.75 | H39: 121.75 | I39: 121.75 | J39: 121.75 | K39: 121.75 | L39: 121.75 | M39: 121.75
A40: benzine | B40: 122 | C40: =26+111 -> 137 | D40: =50+111+113 -> 274 | E40: =120+125 -> 245 | F40: =116+90 -> 206 | G40: 107 | H40: =116+121 -> 237 | I40: =35+100+145 -> 280 | J40: 139 | K40: 120 | L40: 120 | M40: 120
A41: Auto reperatie | F41: 1200 | J41: 743
A42: bankkosten | B42: =14+25+49 -> 88 | C42: =55+27 -> 82 | D42: =90+28 -> 118 | E42: 26 | F42: =231+26 -> 257 | G42: =102+465.85+261+40.79 -> 869.64 | H42: =120+28.99 -> 148.99 | I42: =116.52+31.06 -> 147.58 | K42: 100 | L42: 100 | M42: 100
A44: Belasting | I44: 374
A46: teamvergaderingen huur zaaltje en eten / drank
A48: boekhouder | C48: 1742 | D48: =371+78+155 -> 604 | I48: 435.85 | M48: 450
A50: klein materiaal voor danslessen
A51: Les benodigdheden
A52: Activiteiten | B52: =23.4+29.37+169.9+178+176.22+46 -> 622.89 | D52: =100+143+22+104+61+21+60+601+44+65+35 -> 1256 | E52: =94+122 -> 216 | F52: 128 | G52: =450+250 -> 700 | H52: 89.29 | I52: =25+60+388+275+210 -> 958 | L52: 800
...

Sheet Extra activiteiten
A1: Maand | B1: Activiteit | C1: Verwachte verkoop | D1: Prijs per activiteit | E1: Verwachte omzet | F1: Marketingstrategie | G1: Verkochte aantal | H1: Totaal | J1: Maand | K1: Totaal per maand
A2: September | B2: Selectie bijdrage | C2: 1 | D2: 8730 | E2: =C2*D2 -> 8730 | G2: 1 | H2: =G2*D2 -> 8730 | J2: augustus
A3: September | B3: Inschrijfkosten | C3: 80 | D3: 10 | E3: =C3*D3 -> 800 | F3: (Voor het hele jaar) | G3: 70 | H3: =G3*D3 -> 700 | J3: september | K3: =H2+H3+H4 -> 11430
A4: September | B4: Sponsoring Selectie | C4: 2 | D4: 1000 | E4: =C4*D4 -> 2000 | G4: 2 | H4: =G4*D4 -> 2000 | J4: oktober | K4: =H6+H7+H8+H9+H10+H11 -> 695.5
J5: november | K5: =H12+H13+H14 -> 1206
A6: Oktober | B6: Partijtje | C6: 1 | D6: 235 | E6: =C6*D6 -> 235 | G6: 1 | H6: =G6*D6 -> 235 | J6: december | K6: =H16+H17+H18+H19 -> 9975
A7: Oktober | B7: Herfst 6+ | C7: 25 | D7: 12.5 | E7: =C7*D7 -> 312.5 | G7: 25 | H7: =G7*D7 -> 312.5 | J7: januari | K7: =H20+H21+H22+H23 -> 425
A8: Oktober | B8: Herfst kleuters | C8: 12 | D8: 6.5 | E8: =C8*D8 -> 78 | G8: 12 | H8: =G8*D8 -> 78 | J8: februari | K8: =H25+H26+H27+H28 -> 220
E9: =C9*D9 -> 0 | H9: =G9*D9 -> 0 | J9: maart | K9: =H30+H31+H32+H33 -> 2195
E10: =C10*D10 -> 0 | H10: =G10*D10 -> 0 | J10: april | K10: =H35+H36+H37 -> 220
A11: November | B11: Kinderopvang | C11: 1 | D11: 70 | E11: =C11*D11 -> 70 | G11: 1 | H11: =G11*D11 -> 70 | J11: mei | K11: =H38+H39+H40+H41 -> 41040
A12: November | B12: Merchendise | C12: 1 | D12: 550 | E12: =C12*D12 -> 550 | G12: 1 | H12: =G12*D12 -> 550 | J12: juni | K12: =H43+H44 -> 422.5
A13: November | B13: Halloween | C13: 56 | D13: 8.5 | E13: =C13*D13 -> 476 | G13: 56 | H13: =G13*D13 -> 476 | J13: juli
A14: November | B14: Lessen Ichthus | C14: 2 | D14: 90 | E14: =C14*D14 -> 180 | G14: 2 | H14: =G14*D14 -> 180
E15: =C15*D15 -> 0 | H15: =G15*D15 -> 0
A16: December | B16: Pietenochtend | C16: 40 | D16: 6.5 | E16: =C16*D16 -> 260 | G16: 50 | H16: =G16*D16 -> 325
A17: December | B17: Kerstshow | C17: 800 | D17: 11 | E17: =C17*D17 -> 8800 | G17: 800 | H17: =G17*D17 -> 8800
A18: December | B18: Merchandise | C18: 1 | D18: 780 | E18: =C18*D18 -> 780 | G18: 1 | H18: =G18*D18 -> 780
A19: December | B19: Kinderopvang | C19: 1 | D19: 70 | E19: =C19*D19 -> 70 | G19: 1 | H19: =G19*D19 -> 70
E20: =C20*D20 -> 0 | H20: =G20*D20 -> 0
A21: Januari | B21: Partijtje | C21: 1 | D21: 425 | E21: =C21*D21 -> 425 | G21: 1 | H21: =G21*D21 -> 425
A22: Januari | B22: Merch | C22: 1 | D22: 12.5 | E22: =C22*D22 -> 12.5 | H22: =G22*D22 -> 0
E23: =C23*D23 -> 0 | G23: 1 | H23: =G23*D23 -> 0
E24: =C24*D24 -> 0 | H24: =G24*D24 -> 0
A25: Februari | B25: Merchandise | E25: =C25*D25 -> 0 | H25: =G25*D25 -> 0
A26: Februari | B26: Partijtje | C26: 1 | D26: 220 | E26: =C26*D26 -> 220 | G26: 1 | H26: =G26*D26 -> 220
E27: =C27*D27 -> 0 | H27: =G27*D27 -> 0
E28: =C28*D28 -> 0 | H28: =G28*D28 -> 0
E29: =C29*D29 -> 0 | H29: =G29*D29 -> 0
A30: Maart | B30: Partijtje | C30: 1 | D30: 220 | E30: =C30*D30 -> 220 | G30: 1 | H30: =G30*D30 -> 220
A31: Maart | B31: FL Wedstrijd | C31: 43 | D31: 5.5 | E31: =C31*D31 -> 236.5 | G31: 50 | H31: =G31*D31 -> 275
A32: Maart | B32: FL Wedstrijd | C32: 150 | D32: 10 | E32: =C32*D32 -> 1500 | G32: 170 | H32: =G32*D32 -> 1700
A33: Maart | B33: Merchandise | E33: =C33*D33 -> 0 | H33: =G33*D33 -> 0
E34: =C34*D34 -> 0 | H34: =G34*D34 -> 0
A35: April | B35: Partijtje | C35: 1 | D35: 220 | E35: =C35*D35 -> 220 | G35: 1 | H35: =G35*D35 -> 220
A36: April | B36: Merchandise | E36: =C36*D36 -> 0 | H36: =G36*D36 -> 0
A37: April | E37: =C37*D37 -> 0 | H37: =G37*D37 -> 0
E38: =C38*D38 -> 0 | H38: =G38*D38 -> 0
A39: Mei | B39: Merchandise | C39: 1 | D39: 500 | E39: =C39*D39 -> 500 | G39: 1 | H39: =G39*D39 -> 500
A40: Mei | B40: Voorstelling | C40: 1 | D40: 40540 | E40: =C40*D40 -> 40540 | G40: 1 | H40: =G40*D40 -> 40540
...

Sheet Inkomstenbelasting
A1: Inkomstenbelasting Nederland
A2: Op dit tabblad zie je hoe de berekening voor de inkomstenbelasting is opgebouwd. Let op: Dit is een inschatting!
A4: Heb je recht op startersaftrek in 2025? | C4: Nee | E4: Heb je recht op startersaftrek in 2025? | G4: Nee
A6: Financieel plan - Doelen | C6: 2025 | E6: Financieel plan - Werkelijkheid | G6: 2025
A7: Winst uit onderneming | C7: ='Doel vs Werkelijkheid'!D14 | E7: Winst uit onderneming | G7: ='Doel vs Werkelijkheid'!K14 -> 86454.555
A8: Zelfstandigenaftrek | C8: -2470 | E8: Zelfstandigenaftrek | G8: -2470
A9: Startersaftrek | C9: =IF(C4="Ja",-2123,0) -> 0 | E9: Startersaftrek | G9: =IF(G4="Ja",-2123,0) -> 0
A10: MKB-winstvrijstelling | C10: =MIN(0,-(C7+SUM(C8:C9))*0.127) -> 0 | E10: MKB-winstvrijstelling | G10: =MIN(0,-(G7+SUM(G8:G9))*0.127) -> -10666.039
A11: Belastbaar inkomen box 1 | C11: =MAX(C7+SUM(C8:C10),0) -> 0 | E11: Belastbaar inkomen box 1 | G11: =MAX(G7+SUM(G8:G10),0) -> 73318.517
A13: Belasting box 1 | C13: =MIN(76817,C11)*0.3664 + MAX(C11-76817,0)*0.495 -> 0 | E13: Belasting box 1 | G13: =MIN(76817,G11)*0.3664 + MAX(G11-76817,0)*0.495 -> 26863.905
A14: Algemene heffingskorting | C14: =-IF(AND(C11<24813,C11>0),3362,IF(AND(C11>=24818,C11<75518),(3362-0.0663*(C11-24812)),0)) -> 0 | E14: Algemene heffingskorting | G14: =-IF(AND(G11<24813,G11>0),3362,IF(AND(G11>=24818,G11<75518),(3362-0.0663*(G11-24812)),0)) -> -146.01794
A15: Arbeidskorting | C15: =-IF(AND(C7<11491,C7>0),0.08425*C7,IF(AND(C7>=11491,C7<24821),(968+0.31433*(C7-11490)),IF(AND(C7>=24821,C7<39958),(5158+0.02471*(C7-24820)),IF(AND(C7>=39958,C7<124935),(5532-0.0651*(C7-39958)),0)))) -> 0 | E15: Arbeidskorting | G15: =-IF(AND(G7<11491,G7>0),0.08425*G7,IF(AND(G7>=11491,G7<24821),(968+0.31433*(G7-11490)),IF(AND(G7>=24821,G7<39958),(5158+0.02471*(G7-24820)),IF(AND(G7>=39958,G7<124935),(5532-0.0651*(G7-39958)),0)))) -> -2505.0742
A16: Verschuldigde inkomensbelasting | C16: =MAX(0,C13+C14+C15) -> 0 | E16: Verschuldigde inkomensbelasting | G16: =MAX(0,G13+G14+G15) -> 24212.812
A17: Inkomensafhankelijk bijdrage Zvw | C17: =MIN(C11,71628)*0.0532 -> 0 | E17: Inkomensafhankelijk bijdrage Zvw | G17: =MIN(G11,71628)*0.0532 -> 3810.6096
A18: Totaal inkomstenbelasting en premie Zvw | C18: =C16+C17 -> 0 | E18: Totaal inkomstenbelasting en premie Zvw | G18: =G16+G17 -> 28023.422
A19: % van de winst | C19: =IFERROR(C18/C7,"") | E19: % van de winst | G19: =IFERROR(G18/G7,"") -> 0.32414049 | H19: =G19 -> 0.32414049
A21: Inkomstenbelasting Belgie
A22: Op dit tabblad zie je hoe de berekening voor de inkomstenbelasting is opgebouwd. Let op: Dit is een inschatting!
A24: Financieel plan - Doelen | C24: 2025 | E24: Financieel plan - Werkelijkheid | G24: 2025
A25: Winst uit onderneming | C25: ='Doel vs Werkelijkheid'!D32 | E25: Winst uit onderneming | G25: ='Doel vs Werkelijkheid'!K32
A26: Sociale bijdrage | C26: =IFS(C25<16861.46, 898.28*4,AND(C25>16861.46,C25<72810.95),20.5%*C25,AND(C25>72810.95,C25<107300.3),14.16%*C25,C25>107300.3,5148.1*4) -> 3593.12 | E26: Sociale bijdrage | G26: =IFS(G25<16861.46, 898.28*4,AND(G25>16861.46,G25<72810.95),20.5%*G25,AND(G25>72810.95,G25<107300.3),14.16%*G25,G25>107300.3,5148.1*4) -> 3593.12
A27: Belastbaar inkomen box 1 | C27: =MAX(C25-C26,0) -> 0 | E27: Belastbaar inkomen box 1 | G27: =MAX(G25-G26,0) -> 0
A29: Schijf 1 | C29: =MIN(C27,15200)*25% -> 0 | E29: Schijf 1 | G29: =MIN(G27,15200)*25% -> 0
A30: Schijf 2 | C30: =max(0,(MIN(C27,26830)-15200)*40%) -> 0 | E30: Schijf 2 | G30: =max(0,(MIN(G27,26830)-15200)*40%) -> 0
A31: Schijf 3 | C31: =MAX(0,(MIN(C27,46440)-26830)*45%) -> 0 | E31: Schijf 3 | G31: =MAX(0,(MIN(G27,46440)-26830)*45%) -> 0
A32: Schijf 4 | C32: =Max(C27-46440,0)*50% -> 0 | E32: Schijf 4 | G32: =Max(G27-46440,0)*50% -> 0
A33: Sociale bijdrage | C33: =C26 -> 3593.12 | E33: Sociale bijdrage | G33: =G26 -> 3593.12
A34: Belastingvrije som | C34: =IF(C27<10160,0,-10160*25%) -> 0 | E34: Belastingvrije som | G34: =IF(G27<10160,0,-10160*25%) -> 0
A35: Totaal inkomstenbelasting en premie Zvw | C35: =SUM(C29:C34) -> 3593.12 | E35: Totaal inkomstenbelasting en premie Zvw | G35: =SUM(G29:G34) -> 3593.12
A36: % van de winst | C36: =IFERROR(C35/C25,"") | E36: % van de winst | G36: =IFERROR(G35/G25,"")

Sheet Jaarbetalingen
A1: Lesdag | B1: Lestijd | C1: Minuten les | D1: Naam les | E1: Aantal lessen deze maand | F1: Docent | G1: Tarief docent | H1: Tarief docent per les | I1: Locatie | J1: Zaalhuur per uur | K1: Zaalhuur per les | L1: Aantal leden tarief 1 | M1: Type lidmaatschap (Letop! alleen jaarbetalingen!!) | N1: Tarief 1 | O1: Aantal leden tarief 2 | P1: Type lidmaatschap (Letop! alleen jaarbetalingen!!) 2 | Q1: Tarief 2 | R1: Aantal leden tarief 3 | S1: Type lidmaatschap (Letop! alleen jaarbetalingen!!) 3 | T1: Tarief 3 | U1: Aantal leden tarief 4 | V1: Type lidmaatschap (Letop! alleen jaarbetalingen!!) 4 | W1: Tarief 4 | X1: Aantal leden tarief 5 | Y1: Type lidmaatschap (Letop! alleen jaarbetalingen!!) 5 | Z1: Tarief 5 | AA1: Aantal leden tarief 6 | AB1: Type lidmaatschap (Letop! alleen jaarbetalingen!!) 6 | AC1: Tarief 6 | AD1: Totaal aantal leden | AE1: Kosten per maand | AF1: Inkomsten voor komend seizoen | AG1: Winst per maand
A2: =Rooster!A3 | B2: =Rooster!B3 | C2: =Rooster!C3 | D2: =Rooster!D3 | N2: =IFERROR(VLOOKUP(M2, Tarieven[#ALL], 10, FALSE), "0") -> 0 | Q2: =IFERROR(VLOOKUP(P2, Tarieven[#ALL], 10, FALSE), "0") -> 0 | T2: =IFERROR(VLOOKUP(S2, Tarieven[#ALL], 10, FALSE), "0") -> 0 | W2: =IFERROR(VLOOKUP(V2, Tarieven!$A$1:$J$150, 10, FALSE), "0") -> 0 | Z2: =IFERROR(VLOOKUP(Y2, Tarieven[#ALL], 10, FALSE), "0") -> 0 | AC2: =IFERROR(VLOOKUP(AB2, Tarieven[#ALL], 10, FALSE), "0") -> 0 | AD2: =SUM(L2+O2+R2+U2+X2+AA2) -> 0 | AE2: =SUM(H2+K2)*E2 -> 0 | AF2: =SUM((L2*N2)+(O2*Q2)+(R2*T2)+(U2*W2)+(X2*Z2)+(AA2*AC2)) -> 0 | AG2: =SUM(AF2-AE2) -> 0
A3: =Rooster!A4 | B3: =Rooster!B4 | C3: =Rooster!C4 | D3: =Rooster!D4 | N3: =IFERROR(VLOOKUP(M3, Tarieven[#ALL], 10, FALSE), "0") -> 0 | Q3: =IFERROR(VLOOKUP(P3, Tarieven[#ALL], 10, FALSE), "0") -> 0 | T3: =IFERROR(VLOOKUP(S3, Tarieven[#ALL], 10, FALSE), "0") -> 0 | W3: =IFERROR(VLOOKUP(V3, Tarieven!$A$1:$J$150, 10, FALSE), "0") -> 0 | Z3: =IFERROR(VLOOKUP(Y3, Tarieven[#ALL], 10, FALSE), "0") -> 0 | AC3: =IFERROR(VLOOKUP(AB3, Tarieven[#ALL], 10, FALSE), "0") -> 0 | AD3: =SUM(L3+O3+R3+U3+X3+AA3) -> 0 | AE3: =SUM(H3+K3)*E3 -> 0 | AF3: =SUM((L3*N3)+(O3*Q3)+(R3*T3)+(U3*W3)+(X3*Z3)+(AA3*AC3)) -> 0 | AG3: =SUM(AF3-AE3) -> 0 | AI3: =SUM(Tabel2[Inkomsten voor komend seizoen]) -> 57241.19
A4: =Rooster!A5 -> Maandag | B4: =Rooster!B5 -> 0.625 | C4: =Rooster!C5 -> 60 | D4: =Rooster!D5 -> Kleuterdans | N4: =IFERROR(VLOOKUP(M4, Tarieven[#ALL], 10, FALSE), "0") -> 0 | Q4: =IFERROR(VLOOKUP(P4, Tarieven[#ALL], 10, FALSE), "0") -> 0 | T4: =IFERROR(VLOOKUP(S4, Tarieven[#ALL], 10, FALSE), "0") -> 0 | W4: =IFERROR(VLOOKUP(V4, Tarieven!$A$1:$J$150, 10, FALSE), "0") -> 0 | Z4: =IFERROR(VLOOKUP(Y4, Tarieven[#ALL], 10, FALSE), "0") -> 0 | AC4: =IFERROR(VLOOKUP(AB4, Tarieven[#ALL], 10, FALSE), "0") -> 0 | AD4: =SUM(L4+O4+R4+U4+X4+AA4) -> 0 | AE4: =SUM(H4+K4)*E4 -> 0 | AF4: =SUM((L4*N4)+(O4*Q4)+(R4*T4)+(U4*W4)+(X4*Z4)+(AA4*AC4)) -> 0 | AG4: =SUM(AF4-AE4) -> 0
A5: =Rooster!A6 -> Maandag | B5: =Rooster!B6 -> 0.625 | C5: =Rooster!C6 -> 60 | D5: =Rooster!D6 -> Streetdance 6+ | N5: =IFERROR(VLOOKUP(M5, Tarieven!$A$1:$J$150, 10, FALSE), "0") -> 0 | Q5: =IFERROR(VLOOKUP(P5, Tarieven!$A$1:$J$150, 10, FALSE), "0") -> 0 | T5: =IFERROR(VLOOKUP(S5, Tarieven!$A$1:$J$150, 10, FALSE), "0") -> 0 | W5: =IFERROR(VLOOKUP(V5, Tarieven!$A$1:$J$150, 10, FALSE), "0") -> 0 | Z5: =IFERROR(VLOOKUP(Y5, Tarieven[#ALL], 10, FALSE), "0") -> 0 | AC5: =IFERROR(VLOOKUP(AB5, Tarieven[#ALL], 10, FALSE), "0") -> 0 | AD5: =SUM(L5+O5+R5+U5+X5+AA5) -> 0 | AF5: =SUM((L5*N5)+(O5*Q5)+(R5*T5)+(U5*W5)+(X5*Z5)+(AA5*AC5)) -> 0 | AG5: =SUM(L5+O5+R5+AD5) -> 0
A6: =Rooster!A7 -> Maandag | B6: =Rooster!B7 -> 0.66666667 | C6: =Rooster!C7 -> 60 | D6: =Rooster!D7 -> Urban-Pop-Show 10+ | L6: 3 | M6: 1x per week | N6: =IFERROR(VLOOKUP(M6, Tarieven!$A$1:$J$150, 10, FALSE), "0") -> 279 | O6: 1 | P6: Cheer regulier +1 | Q6: =IFERROR(VLOOKUP(P6, Tarieven!$A$1:$J$150, 10, FALSE), "0") -> 289.5 | T6: =IFERROR(VLOOKUP(S6, Tarieven!$A$1:$J$150, 10, FALSE), "0") -> 0 | W6: =IFERROR(VLOOKUP(V6, Tarieven!$A$1:$J$150, 10, FALSE), "0") -> 0 | Z6: =IFERROR(VLOOKUP(Y6, Tarieven[#ALL], 10, FALSE), "0") -> 0 | AC6: =IFERROR(VLOOKUP(AB6, Tarieven[#ALL], 10, FALSE), "0") -> 0 | AD6: =SUM(L6+O6+R6+U6+X6+AA6) -> 4 | AE6: 1x per week | AF6: =SUM((L6*N6)+(O6*Q6)+(R6*T6)+(U6*W6)+(X6*Z6)+(AA6*AC6)) -> 1126.5 | AG6: =SUM(L6+O6+R6+AD6) -> 8
A7: =Rooster!A8 -> Maandag | B7: =Rooster!B8 -> 0.70833333 | C7: =Rooster!C8 -> 60 | D7: =Rooster!D8 -> Urban-Pop-Show 12+ | L7: 4 | M7: 1x per week | N7: =IFERROR(VLOOKUP(M7, Tarieven!$A$1:$J$150, 10, FALSE), "0") -> 279 | O7: 2 | P7: 2x per week | Q7: =IFERROR(VLOOKUP(P7, Tarieven!$A$1:$J$150, 10, FALSE), "0") -> 279 | R7: 1 | S7: Cheer regulier +1 | T7: =IFERROR(VLOOKUP(S7, Tarieven!$A$1:$J$150, 10, FALSE), "0") -> 289.5 | U7: 4 | V7: Cheer selectie onbeperkt | W7: =IFERROR(VLOOKUP(V7, Tarieven!$A$1:$J$150, 10, FALSE), "0") -> 235 | Z7: =IFERROR(VLOOKUP(Y7, Tarieven[#ALL], 10, FALSE), "0") -> 0 | AC7: =IFERROR(VLOOKUP(AB7, Tarieven[#ALL], 10, FALSE), "0") -> 0 | AD7: =SUM(L7+O7+R7+U7+X7+AA7) -> 11 | AF7: =SUM((L7*N7)+(O7*Q7)+(R7*T7)+(U7*W7)+(X7*Z7)+(AA7*AC7)) -> 2903.5 | AG7: =SUM(L7+O7+R7+AD7) -> 18
A8: =Rooster!A9 -> Maandag | B8: =Rooster!B9 -> 0.75 | C8: =Rooster!C9 -> 60 | D8: =Rooster!D9 -> Selectie Show | N8: =IFERROR(VLOOKUP(M8, Tarieven!$A$1:$J$150, 10, FALSE), "0") -> 0 | O8: 3 | P8: Onbeperkt | Q8: =IFERROR(VLOOKUP(P8, Tarieven!$A$1:$J$150, 10, FALSE), "0") -> 263.625 | R8: 1 | S8: Geen betaling | T8: =IFERROR(VLOOKUP(S8, Tarieven!$A$1:$J$150, 10, FALSE), "0") -> 0 | W8: =IFERROR(VLOOKUP(V8, Tarieven!$A$1:$J$150, 10, FALSE), "0") -> 0 | Z8: =IFERROR(VLOOKUP(Y8, Tarieven[#ALL], 10, FALSE), "0") -> 0 | AC8: =IFERROR(VLOOKUP(AB8, Tarieven[#ALL], 10, FALSE), "0") -> 0 | AD8: =SUM(L8+O8+R8+U8+X8+AA8) -> 4 | AF8: =SUM((L8*N8)+(O8*Q8)+(R8*T8)+(U8*W8)+(X8*Z8)+(AA8*AC8)) -> 790.875 | AG8: =SUM(L8+O8+R8+AD8) -> 8
A9: =Rooster!A10 -> Maandag | B9: =Rooster!B10 -> 0.79166667 | C9: =Rooster!C10 -> 60 | D9: =Rooster!D10 -> Commercial 16+ | L9: 1 | M9: 1x per week | N9: =IFERROR(VLOOKUP(M9, Tarieven!$A$1:$J$150, 10, FALSE), "0") -> 279 | O9: 2 | P9: Onbeperkt | Q9: =IFERROR(VLOOKUP(P9, Tarieven!$A$1:$J$150, 10, FALSE), "0") -> 263.625 | R9: 1 | S9: 3x per week | T9: =IFERROR(VLOOKUP(S9, Tarieven!$A$1:$J$150, 10, FALSE), "0") -> 279 | U9: 1 | V9: Geen betaling | W9: =IFERROR(VLOOKUP(V9, Tarieven!$A$1:$J$150, 10, FALSE), "0") -> 0 | Z9: =IFERROR(VLOOKUP(Y9, Tarieven[#ALL], 10, FALSE), "0") -> 0 | AC9: =IFERROR(VLOOKUP(AB9, Tarieven[#ALL], 10, FALSE), "0") -> 0 | AD9: =SUM(L9+O9+R9+U9+X9+AA9) -> 5 | AF9: =SUM((L9*N9)+(O9*Q9)+(R9*T9)+(U9*W9)+(X9*Z9)+(AA9*AC9)) -> 1085.25 | AG9: =SUM(L9+O9+R9+AD9) -> 9
A10: =Rooster!A11 -> Maandag | B10: =Rooster!B11 -> 0.83333333 | C10: =Rooster!C11 -> 60 | D10: =Rooster!D11 -> Commercial 20+ | L10: 1 | M10: Volwassenen 2x | N10: =IFERROR(VLOOKUP(M10, Tarieven!$A$1:$J$150, 10, FALSE), "0") -> 266.625 | O10: 3 | P10: Volwassenen 1x | Q10: =IFERROR(VLOOKUP(P10, Tarieven!$A$1:$J$150, 10, FALSE), "0") -> 266.23 | R10: 4 | S10: Geen betaling | T10: =IFERROR(VLOOKUP(S10, Tarieven!$A$1:$J$150, 10, FALSE), "0") -> 0 | W10: =IFERROR(VLOOKUP(V10, Tarieven!$A$1:$J$150, 10, FALSE), "0") -> 0 | Z10: =IFERROR(VLOOKUP(Y10, Tarieven[#ALL], 10, FALSE), "0") -> 0 | AC10: =IFERROR(VLOOKUP(AB10, Tarieven[#ALL], 10, FALSE), "0") -> 0 | AD10: =SUM(L10+O10+R10+U10+X10+AA10) -> 8 | AF10: =SUM((L10*N10)+(O10*Q10)+(R10*T10)+(U10*W10)+(X10*Z10)+(AA10*AC10)) -> 1065.315 | AG10: =SUM(L10+O10+R10+AD10) -> 16
A11: =Rooster!A12 -> Maandag | B11: =Rooster!B12 -> 0.875 | C11: =Rooster!C12 -> 60 | D11: =Rooster!D12 -> Jazz 20+ | L11: 1 | M11: Volwassenen 2x | N11: =IFERROR(VLOOKUP(M11, Tarieven!$A$1:$J$150, 10, FALSE), "0") -> 266.625 | Q11: =IFERROR(VLOOKUP(P11, Tarieven!$A$1:$J$150, 10, FALSE), "0") -> 0 | R11: 3 | S11: Geen betaling | T11: =IFERROR(VLOOKUP(S11, Tarieven!$A$1:$J$150, 10, FALSE), "0") -> 0 | W11: =IFERROR(VLOOKUP(V11, Tarieven!$A$1:$J$150, 10, FALSE), "0") -> 0 | Z11: =IFERROR(VLOOKUP(Y11, Tarieven[#ALL], 10, FALSE), "0") -> 0 | AC11: =IFERROR(VLOOKUP(AB11, Tarieven[#ALL], 10, FALSE), "0") -> 0 | AD11: =SUM(L11+O11+R11+U11+X11+AA11) -> 4 | AE11: 1x per week | AF11: =SUM((L11*N11)+(O11*Q11)+(R11*T11)+(U11*W11)+(X11*Z11)+(AA11*AC11)) -> 266.625 | AG11: =SUM(L11+O11+R11+AD11) -> 8
A12: =Rooster!A13 -> Maandag | B12: =Rooster!B13 -> 0.66666667 | C12: =Rooster!C13 -> 60 | D12: =Rooster!D13 -> Streetdance 6+ | L12: 2 | M12: 1x per week | N12: =IFERROR(VLOOKUP(M12, Tarieven!$A$1:$J$150, 10, FALSE), "0") -> 279 | Q12: =IFERROR(VLOOKUP(P12, Tarieven!$A$1:$J$150, 10, FALSE), "0") -> 0 | T12: =IFERROR(VLOOKUP(S12, Tarieven!$A$1:$J$150, 10, FALSE), "0") -> 0 | W12: =IFERROR(VLOOKUP(V12, Tarieven!$A$1:$J$150, 10, FALSE), "0") -> 0 | Z12: =IFERROR(VLOOKUP(Y12, Tarieven[#ALL], 10, FALSE), "0") -> 0 | AC12: =IFERROR(VLOOKUP(AB12, Tarieven[#ALL], 10, FALSE), "0") -> 0 | AD12: =SUM(L12+O12+R12+U12+X12+AA12) -> 2 | AF12: =SUM((L12*N12)+(O12*Q12)+(R12*T12)+(U12*W12)+(X12*Z12)+(AA12*AC12)) -> 558 | AG12: =SUM(L12+O12+R12+AD12) -> 4
A13: =Rooster!A14 -> Maandag | B13: =Rooster!B14 -> 0.70833333 | C13: =Rooster!C14 -> 60 | D13: =Rooster!D14 -> Streetdance 8+ | L13: 10 | M13: 1x per week | N13: =IFERROR(VLOOKUP(M13, Tarieven!$A$1:$J$150, 10, FALSE), "0") -> 279 | O13: 3 | P13: 2x per week | Q13: =IFERROR(VLOOKUP(P13, Tarieven!$A$1:$J$150, 10, FALSE), "0") -> 279 | T13: =IFERROR(VLOOKUP(S13, Tarieven!$A$1:$J$150, 10, FALSE), "0") -> 0 | W13: =IFERROR(VLOOKUP(V13, Tarieven!$A$1:$J$150, 10, FALSE), "0") -> 0 | Z13: =IFERROR(VLOOKUP(Y13, Tarieven[#ALL], 10, FALSE), "0") -> 0 | AC13: =IFERROR(VLOOKUP(AB13, Tarieven[#ALL], 10, FALSE), "0") -> 0 | AD13: =SUM(L13+O13+R13+U13+X13+AA13) -> 13 | AE13: 1x per week | AF13: =SUM((L13*N13)+(O13*Q13)+(R13*T13)+(U13*W13)+(X13*Z13)+(AA13*AC13)) -> 3627 | AG13: =SUM(L13+O13+R13+AD13) -> 26
A14: =Rooster!A15 -> Dinsdag | B14: =Rooster!B15 -> 0.66666667 | C14: =Rooster!C15 -> 60 | D14: =Rooster!D15 -> Modern 8+ | L14: 4 | M14: 2x per week | N14: =IFERROR(VLOOKUP(M14, Tarieven!$A$1:$J$150, 10, FALSE), "0") -> 279 | O14: 2 | P14: Cheer regulier +2 | Q14: =IFERROR(VLOOKUP(P14, Tarieven!$A$1:$J$150, 10, FALSE), "0") -> 270.16667 | R14: 2 | S14: 1x per week | T14: =IFERROR(VLOOKUP(S14, Tarieven!$A$1:$J$150, 10, FALSE), "0") -> 279 | W14: =IFERROR(VLOOKUP(V14, Tarieven!$A$1:$J$150, 10, FALSE), "0") -> 0 | Z14: =IFERROR(VLOOKUP(Y14, Tarieven[#ALL], 10, FALSE), "0") -> 0 | AC14: =IFERROR(VLOOKUP(AB14, Tarieven[#ALL], 10, FALSE), "0") -> 0 | AD14: =SUM(L14+O14+R14+U14+X14+AA14) -> 8 | AF14: =SUM((L14*N14)+(O14*Q14)+(R14*T14)+(U14*W14)+(X14*Z14)+(AA14*AC14)) -> 2214.3333 | AG14: =SUM(L14+O14+R14+AD14) -> 16
A15: =Rooster!A16 -> Dinsdag | B15: =Rooster!B16 -> 0.70833333 | C15: =Rooster!C16 -> 60 | D15: =Rooster!D16 -> Selectie show 8+ | F15: =Rooster!E16 -> Eigenaar | G15: =IFERROR(VLOOKUP(F15, Docenten!$A$2:$G$30, 7, FALSE), "0") -> 0 | H15: =SUM(G15/60)*C15 -> 0 | I15: =Rooster!H16 -> Santpoort Zuid | J15: =IFERROR(VLOOKUP(I15, Locaties!$A$2:$G$15, 7, FALSE), "0") -> 18.9 | K15: =SUM(J15/60)*C15 -> 18.9 | L15: 4 | M15: Cheer regulier +2 | N15: =IFERROR(VLOOKUP(M15, Tarieven!$A$1:$J$150, 10, FALSE), "0") -> 270.16667 | O15: 2 | P15: Cheer regulier +1 | Q15: =IFERROR(VLOOKUP(P15, Tarieven!$A$1:$J$150, 10, FALSE), "0") -> 289.5 | R15: 1 | S15: 2x per week | T15: =IFERROR(VLOOKUP(S15, Tarieven!$A$1:$J$150, 10, FALSE), "0") -> 279 | W15: =IFERROR(VLOOKUP(V15, Tarieven!$A$1:$J$150, 10, FALSE), "0") -> 0 | Z15: =IFERROR(VLOOKUP(Y15, Tarieven[#ALL], 10, FALSE), "0") -> 0 | AC15: =IFERROR(VLOOKUP(AB15, Tarieven[#ALL], 10, FALSE), "0") -> 0 | AD15: =SUM(L15+O15+R15+U15+X15+AA15) -> 7 | AF15: =SUM((L15*N15)+(O15*Q15)+(R15*T15)+(U15*W15)+(X15*Z15)+(AA15*AC15)) -> 1938.6667 | AG15: =SUM(L15+O15+R15+AD15) -> 14
A16: =Rooster!A17 -> Dinsdag | B16: =Rooster!B17 -> 0.75 | C16: =Rooster!C17 -> 90 | D16: =Rooster!D17 -> Selectie Cheer | F16: =Rooster!E17 -> Eigenaar | G16: =IFERROR(VLOOKUP(F16, Docenten!$A$2:$G$30, 7, FALSE), "0") -> 0 | H16: =SUM(G16/60)*C16 -> 0 | I16: =Rooster!H17 -> Santpoort Zuid | J16: =IFERROR(VLOOKUP(I16, Locaties!$A$2:$G$15, 7, FALSE), "0") -> 18.9 | K16: =SUM(J16/60)*C16 -> 28.35 | L16: 1 | M16: Cheer selecie +1 | N16: =IFERROR(VLOOKUP(M16, Tarieven!$A$1:$J$150, 10, FALSE), "0") -> 308.5 | O16: 2 | P16: Cheer selectie +2 | Q16: =IFERROR(VLOOKUP(P16, Tarieven!$A$1:$J$150, 10, FALSE), "0") -> 298.66667 | T16: =IFERROR(VLOOKUP(S16, Tarieven!$A$1:$J$150, 10, FALSE), "0") -> 0 | U16: 5 | V16: Cheer selectie onbeperkt | W16: =IFERROR(VLOOKUP(V16, Tarieven!$A$1:$J$150, 10, FALSE), "0") -> 235 | Z16: =IFERROR(VLOOKUP(Y16, Tarieven[#ALL], 10, FALSE), "0") -> 0 | AC16: =IFERROR(VLOOKUP(AB16, Tarieven[#ALL], 10, FALSE), "0") -> 0 | AD16: =SUM(L16+O16+R16+U16+X16+AA16) -> 8 | AE16: 2x per week | AF16: =SUM((L16*N16)+(O16*Q16)+(R16*T16)+(U16*W16)+(X16*Z16)+(AA16*AC16)) -> 2080.8333 | AG16: =SUM(L16+O16+R16+AD16) -> 11
A17: =Rooster!A18 -> Dinsdag | B17: =Rooster!B18 -> 0.8125 | C17: =Rooster!C18 -> 60 | D17: =Rooster!D18 -> Hiphop 15+ | F17: =Rooster!E18 -> Eigenaar | G17: =IFERROR(VLOOKUP(F17, Docenten!$A$2:$G$30, 7, FALSE), "0") -> 0 | H17: =SUM(G17/60)*C17 -> 0 | I17: =Rooster!H18 -> Santpoort Zuid | J17: =IFERROR(VLOOKUP(I17, Locaties!$A$2:$G$15, 7, FALSE), "0") -> 18.9 | K17: =SUM(J17/60)*C17 -> 18.9 | L17: 1 | M17: Cheer selectie onbeperkt | N17: =IFERROR(VLOOKUP(M17, Tarieven!$A$1:$J$150, 10, FALSE), "0") -> 235 | O17: 3 | P17: 2x per week | Q17: =IFERROR(VLOOKUP(P17, Tarieven!$A$1:$J$150, 10, FALSE), "0") -> 279 | R17: 2 | S17: 3x per week | T17: =IFERROR(VLOOKUP(S17, Tarieven!$A$1:$J$150, 10, FALSE), "0") -> 279 | U17: 1 | V17: 1x per week | W17: =IFERROR(VLOOKUP(V17, Tarieven!$A$1:$J$150, 10, FALSE), "0") -> 279 | X17: 2 | Y17: Onbeperkt | Z17: =IFERROR(VLOOKUP(Y17, Tarieven[#ALL], 10, FALSE), "0") -> 263.625 | AC17: =IFERROR(VLOOKUP(AB17, Tarieven[#ALL], 10, FALSE), "0") -> 0 | AD17: =SUM(L17+O17+R17+U17+X17+AA17) -> 9 | AE17: Cheer regulier +1 | AF17: =SUM((L17*N17)+(O17*Q17)+(R17*T17)+(U17*W17)+(X17*Z17)+(AA17*AC17)) -> 2436.25 | AG17: =SUM(L17+O17+R17+AD17) -> 15
A18: =Rooster!A19 -> Woensdag | B18: =Rooster!B19 -> 0.60416667 | C18: =Rooster!C19 -> 60 | D18: =Rooster!D19 -> Streetdance 6+ | F18: =Rooster!E19 -> Julia | G18: =IFERROR(VLOOKUP(F18, Docenten!$A$2:$G$30, 7, FALSE), "0") -> 15 | H18: =SUM(G18/60)*C18 -> 15 | I18: =Rooster!H19 -> Santpoort Noord | J18: =IFERROR(VLOOKUP(I18, Locaties!$A$2:$G$15, 7, FALSE), "0") -> 14.2 | K18: =SUM(J18/60)*C18 -> 14.2 | L18: 9 | M18: 1x per week | N18: =IFERROR(VLOOKUP(M18, Tarieven!$A$1:$J$150, 10, FALSE), "0") -> 279 | Q18: =IFERROR(VLOOKUP(P18, Tarieven!$A$1:$J$150, 10, FALSE), "0") -> 0 | T18: =IFERROR(VLOOKUP(S18, Tarieven!$A$1:$J$150, 10, FALSE), "0") -> 0 | W18: =IFERROR(VLOOKUP(V18, Tarieven!$A$1:$J$150, 10, FALSE), "0") -> 0 | Z18: =IFERROR(VLOOKUP(Y18, Tarieven[#ALL], 10, FALSE), "0") -> 0 | AC18: =IFERROR(VLOOKUP(AB18, Tarieven[#ALL], 10, FALSE), "0") -> 0 | AD18: =SUM(L18+O18+R18+U18+X18+AA18) -> 9 | AF18: =SUM((L18*N18)+(O18*Q18)+(R18*T18)+(U18*W18)+(X18*Z18)+(AA18*AC18)) -> 2511 | AG18: =SUM(L18+O18+R18+AD18) -> 18
A19: =Rooster!A20 -> Woensdag | B19: =Rooster!B20 -> 0.64583333 | C19: =Rooster!C20 -> 60 | D19: =Rooster!D20 -> Streetdance 8+ | F19: =Rooster!E20 -> Julia | G19: =IFERROR(VLOOKUP(F19, Docenten!$A$2:$G$30, 7, FALSE), "0") -> 15 | H19: =SUM(G19/60)*C19 -> 15 | I19: =Rooster!H20 -> Santpoort Noord | J19: =IFERROR(VLOOKUP(I19, Locaties!$A$2:$G$15, 7, FALSE), "0") -> 14.2 | K19: =SUM(J19/60)*C19 -> 14.2 | L19: 9 | M19: 1x per week | N19: =IFERROR(VLOOKUP(M19, Tarieven!$A$1:$J$150, 10, FALSE), "0") -> 279 | O19: 1 | P19: 2x per week | Q19: =IFERROR(VLOOKUP(P19, Tarieven!$A$1:$J$150, 10, FALSE), "0") -> 279 | R19: 1 | S19: Cheer regulier +2 | T19: =IFERROR(VLOOKUP(S19, Tarieven!$A$1:$J$150, 10, FALSE), "0") -> 270.16667 | W19: =IFERROR(VLOOKUP(V19, Tarieven!$A$1:$J$150, 10, FALSE), "0") -> 0 | Z19: =IFERROR(VLOOKUP(Y19, Tarieven[#ALL], 10, FALSE), "0") -> 0 | AC19: =IFERROR(VLOOKUP(AB19, Tarieven[#ALL], 10, FALSE), "0") -> 0 | AD19: =SUM(L19+O19+R19+U19+X19+AA19) -> 11 | AF19: =SUM((L19*N19)+(O19*Q19)+(R19*T19)+(U19*W19)+(X19*Z19)+(AA19*AC19)) -> 3060.1667 | AG19: =SUM(L19+O19+R19+AD19) -> 22
A20: =Rooster!A21 -> Woensdag | B20: =Rooster!B21 -> 0.6875 | C20: =Rooster!C21 -> 60 | D20: =Rooster!D21 -> Modern 11+ | F20: =Rooster!E21 -> Julia | G20: =IFERROR(VLOOKUP(F20, Docenten!$A$2:$G$30, 7, FALSE), "0") -> 15 | H20: =SUM(G20/60)*C20 -> 15 | I20: =Rooster!H21 -> Santpoort Noord | J20: =IFERROR(VLOOKUP(I20, Locaties!$A$2:$G$15, 7, FALSE), "0") -> 14.2 | K20: =SUM(J20/60)*C20 -> 14.2 | L20: 4 | M20: 2x per week | N20: =IFERROR(VLOOKUP(M20, Tarieven!$A$1:$J$150, 10, FALSE), "0") -> 279 | O20: 1 | P20: Cheer regulier +1 | Q20: =IFERROR(VLOOKUP(P20, Tarieven!$A$1:$J$150, 10, FALSE), "0") -> 289.5 | R20: 4 | S20: Cheer selectie onbeperkt | T20: =IFERROR(VLOOKUP(S20, Tarieven!$A$1:$J$150, 10, FALSE), "0") -> 235 | W20: =IFERROR(VLOOKUP(V20, Tarieven!$A$1:$J$150, 10, FALSE), "0") -> 0 | Z20: =IFERROR(VLOOKUP(Y20, Tarieven[#ALL], 10, FALSE), "0") -> 0 | AC20: =IFERROR(VLOOKUP(AB20, Tarieven[#ALL], 10, FALSE), "0") -> 0 | AD20: =SUM(L20+O20+R20+U20+X20+AA20) -> 9 | AF20: =SUM((L20*N20)+(O20*Q20)+(R20*T20)+(U20*W20)+(X20*Z20)+(AA20*AC20)) -> 2345.5 | AG20: =SUM(L20+O20+R20+AD20) -> 18
A21: =Rooster!A22 -> Woensdag | B21: =Rooster!B22 -> 0.72916667 | C21: =Rooster!C22 -> 60 | D21: =Rooster!D22 -> Selectie Hiphop 11+ | F21: =Rooster!E22 -> Eigenaar | G21: =IFERROR(VLOOKUP(F21, Docenten!$A$2:$G$30, 7, FALSE), "0") -> 0 | H21: =SUM(G21/60)*C21 -> 0 | I21: =Rooster!H22 -> Santpoort Noord | J21: =IFERROR(VLOOKUP(I21, Locaties!$A$2:$G$15, 7, FALSE), "0") -> 14.2 | K21: =SUM(J21/60)*C21 -> 14.2 | L21: 5 | M21: 2x per week | N21: =IFERROR(VLOOKUP(M21, Tarieven!$A$1:$J$150, 10, FALSE), "0") -> 279 | O21: 2 | P21: Cheer selecie +1 | Q21: =IFERROR(VLOOKUP(P21, Tarieven!$A$1:$J$150, 10, FALSE), "0") -> 308.5 | R21: 1 | S21: Cheer selectie +2 | T21: =IFERROR(VLOOKUP(S21, Tarieven!$A$1:$J$150, 10, FALSE), "0") -> 298.66667 | U21: 3 | V21: Cheer selectie onbeperkt | W21: =IFERROR(VLOOKUP(V21, Tarieven!$A$1:$J$150, 10, FALSE), "0") -> 235 | Z21: =IFERROR(VLOOKUP(Y21, Tarieven[#ALL], 10, FALSE), "0") -> 0 | AC21: =IFERROR(VLOOKUP(AB21, Tarieven[#ALL], 10, FALSE), "0") -> 0 | AD21: =SUM(L21+O21+R21+U21+X21+AA21) -> 11 | AE21: Cheer selecie +1 | AF21: =SUM((L21*N21)+(O21*Q21)+(R21*T21)+(U21*W21)+(X21*Z21)+(AA21*AC21)) -> 3015.6667 | AG21: =SUM(L21+O21+R21+AD21) -> 19
A22: =Rooster!A23 -> Woensdag | B22: =Rooster!B23 -> 0.77083333 | C22: =Rooster!C23 -> 60 | D22: =Rooster!D23 -> Show 12+ | F22: =Rooster!E23 -> Eigenaar | G22: =IFERROR(VLOOKUP(F22, Docenten!$A$2:$G$30, 7, FALSE), "0") -> 0 | H22: =SUM(G22/60)*C22 -> 0 | I22: =Rooster!H23 -> Santpoort Noord | J22: =IFERROR(VLOOKUP(I22, Locaties!$A$2:$G$15, 7, FALSE), "0") -> 14.2 | K22: =SUM(J22/60)*C22 -> 14.2 | L22: 1 | M22: Cheer selecie +1 | N22: =IFERROR(VLOOKUP(M22, Tarieven!$A$1:$J$150, 10, FALSE), "0") -> 308.5 | O22: 3 | P22: 1x per week | Q22: =IFERROR(VLOOKUP(P22, Tarieven!$A$1:$J$150, 10, FALSE), "0") -> 279 | R22: 1 | S22: 3x per week | T22: =IFERROR(VLOOKUP(S22, Tarieven!$A$1:$J$150, 10, FALSE), "0") -> 279 | U22: 3 | V22: Cheer selectie onbeperkt | W22: =IFERROR(VLOOKUP(V22, Tarieven!$A$1:$J$150, 10, FALSE), "0") -> 235 | X22: 1 | Y22: Cheer regulier + onbeperkt | Z22: =IFERROR(VLOOKUP(Y22, Tarieven[#ALL], 10, FALSE), "0") -> 286.75 | AC22: =IFERROR(VLOOKUP(AB22, Tarieven[#ALL], 10, FALSE), "0") -> 0 | AD22: =SUM(L22+O22+R22+U22+X22+AA22) -> 9 | AE22: 2x per week | AF22: =SUM((L22*N22)+(O22*Q22)+(R22*T22)+(U22*W22)+(X22*Z22)+(AA22*AC22)) -> 2416.25 | AG22: =SUM(L22+O22+R22+AD22) -> 14
A23: =Rooster!A24 | B23: =Rooster!B24 | C23: =Rooster!C24 | D23: =Rooster!D24 | F23: =Rooster!E24 | G23: =IFERROR(VLOOKUP(F23, Docenten!$A$2:$G$30, 7, FALSE), "0") -> 0 | H23: =SUM(G23/60)*C23 -> 0 | I23: =Rooster!H24 | J23: =IFERROR(VLOOKUP(I23, Locaties!$A$2:$G$15, 7, FALSE), "0") -> 0 | K23: =SUM(J23/60)*C23 -> 0 | N23: =IFERROR(VLOOKUP(M23, Tarieven!$A$1:$J$150, 10, FALSE), "0") -> 0 | Q23: =IFERROR(VLOOKUP(P23, Tarieven!$A$1:$J$150, 10, FALSE), "0") -> 0 | T23: =IFERROR(VLOOKUP(S23, Tarieven!$A$1:$J$150, 10, FALSE), "0") -> 0 | W23: =IFERROR(VLOOKUP(V23, Tarieven!$A$1:$J$150, 10, FALSE), "0") -> 0 | Z23: =IFERROR(VLOOKUP(Y23, Tarieven[#ALL], 10, FALSE), "0") -> 0 | AC23: =IFERROR(VLOOKUP(AB23, Tarieven[#ALL], 10, FALSE), "0") -> 0 | AD23: =SUM(L23+O23+R23+U23+X23+AA23) -> 0 | AF23: =SUM((L23*N23)+(O23*Q23)+(R23*T23)+(U23*W23)+(X23*Z23)+(AA23*AC23)) -> 0 | AG23: =SUM(L23+O23+R23+AD23) -> 0
A24: =Rooster!A25 -> Donderdag | B24: =Rooster!B25 -> 0.64583333 | C24: =Rooster!C25 -> 60 | D24: =Rooster!D25 -> Showdance 6+ | F24: =Rooster!E25 -> Eigenaar | G24: =IFERROR(VLOOKUP(F24, Docenten!$A$2:$G$30, 7, FALSE), "0") -> 0 | H24: =SUM(G24/60)*C24 -> 0 | I24: =Rooster!H25 -> Santpoort Zuid | J24: =IFERROR(VLOOKUP(I24, Locaties!$A$2:$G$15, 7, FALSE), "0") -> 18.9 | K24: =SUM(J24/60)*C24 -> 18.9 | L24: 4 | M24: 1x per week | N24: =IFERROR(VLOOKUP(M24, Tarieven!$A$1:$J$150, 10, FALSE), "0") -> 279 | Q24: =IFERROR(VLOOKUP(P24, Tarieven!$A$1:$J$150, 10, FALSE), "0") -> 0 | T24: =IFERROR(VLOOKUP(S24, Tarieven!$A$1:$J$150, 10, FALSE), "0") -> 0 | W24: =IFERROR(VLOOKUP(V24, Tarieven!$A$1:$J$150, 10, FALSE), "0") -> 0 | Z24: =IFERROR(VLOOKUP(Y24, Tarieven[#ALL], 10, FALSE), "0") -> 0 | AC24: =IFERROR(VLOOKUP(AB24, Tarieven[#ALL], 10, FALSE), "0") -> 0 | AD24: =SUM(L24+O24+R24+U24+X24+AA24) -> 4 | AF24: =SUM((L24*N24)+(O24*Q24)+(R24*T24)+(U24*W24)+(X24*Z24)+(AA24*AC24)) -> 1116 | AG24: =SUM(L24+O24+R24+AD24) -> 8
A25: =Rooster!A26 -> Donderdag | B25: =Rooster!B26 -> 0.6875 | C25: =Rooster!C26 -> 60 | D25: =Rooster!D26 -> Showdance 8+ | F25: =Rooster!E26 -> Eigenaar | G25: =IFERROR(VLOOKUP(F25, Docenten!$A$2:$G$30, 7, FALSE), "0") -> 0 | H25: =SUM(G25/60)*C25 -> 0 | I25: =Rooster!H26 -> Santpoort Zuid | J25: =IFERROR(VLOOKUP(I25, Locaties!$A$2:$G$15, 7, FALSE), "0") -> 18.9 | K25: =SUM(J25/60)*C25 -> 18.9 | M25: 1x per week | N25: =IFERROR(VLOOKUP(M25, Tarieven!$A$1:$J$150, 10, FALSE), "0") -> 279 | O25: 3 | P25: 2x per week | Q25: =IFERROR(VLOOKUP(P25, Tarieven!$A$1:$J$150, 10, FALSE), "0") -> 279 | R25: 1 | S25: Cheer regulier +2 | T25: =IFERROR(VLOOKUP(S25, Tarieven!$A$1:$J$150, 10, FALSE), "0") -> 270.16667 | W25: =IFERROR(VLOOKUP(V25, Tarieven!$A$1:$J$150, 10, FALSE), "0") -> 0 | Z25: =IFERROR(VLOOKUP(Y25, Tarieven[#ALL], 10, FALSE), "0") -> 0 | AC25: =IFERROR(VLOOKUP(AB25, Tarieven[#ALL], 10, FALSE), "0") -> 0 | AD25: =SUM(L25+O25+R25+U25+X25+AA25) -> 4 | AF25: =SUM((L25*N25)+(O25*Q25)+(R25*T25)+(U25*W25)+(X25*Z25)+(AA25*AC25)) -> 1107.1667 | AG25: =SUM(L25+O25+R25+AD25) -> 8
